[DEBUG] /api/sync_github endpoint hit!
[ERROR] General Exception: cannot access local variable 'os' where it is not associated with a value
[DEBUG] GitHub Sync Result: {'success': False, 'message': "同步失败: cannot access local variable 'os' where it is not associated with a value", 'error': "cannot access local variable 'os' where it is not associated with a value", 'timestamp': '2025-06-04 11:43:45'}
[DEBUG] /api/sync_github endpoint hit!
[DEBUG] 2025-06-04 12:39:40 - [DEBUG] /api/sync_github endpoint hit!
[DEBUG] 2025-06-04 12:39:40 - [DEBUG] Current working directory: D:\PythonSpace\cayden_de_blog
[DEBUG] 2025-06-04 12:39:40 - [DEBUG] Repo dirty: True
[DEBUG] 2025-06-04 12:39:40 - [DEBUG] Committing with message: Auto sync at 2025-06-04 12:39:40
[DEBUG] 2025-06-04 12:39:43 - [DEBUG] Pushing to origin/main
[DEBUG] GitHub Sync Result: {'success': True, 'message': '成功同步到GitHub仓库', 'timestamp': '2025-06-04 12:39:46'}
